{
  "nbformat": 4,
  "nbformat_minor": 0,
  "metadata": {
    "colab": {
      "provenance": [],
      "authorship_tag": "ABX9TyNlUgbsFwqJb/nFi8IwHeKT",
      "include_colab_link": true
    },
    "kernelspec": {
      "name": "python3",
      "display_name": "Python 3"
    },
    "language_info": {
      "name": "python"
    }
  },
  "cells": [
    {
      "cell_type": "markdown",
      "metadata": {
        "id": "view-in-github",
        "colab_type": "text"
      },
      "source": [
        "<a href=\"https://colab.research.google.com/github/N0VA-code/CS4v98_Machine-Learning-based-Hateful-meme-detector/blob/main/Week6.ipynb\" target=\"_parent\"><img src=\"https://colab.research.google.com/assets/colab-badge.svg\" alt=\"Open In Colab\"/></a>"
      ]
    },
    {
      "cell_type": "code",
      "execution_count": null,
      "metadata": {
        "colab": {
          "base_uri": "https://localhost:8080/"
        },
        "id": "DP81FPg7_ksB",
        "outputId": "41878c05-703a-4016-d897-71c5f6c9ee2e"
      },
      "outputs": [
        {
          "output_type": "stream",
          "name": "stdout",
          "text": [
            "Requirement already satisfied: ray in /usr/local/lib/python3.10/dist-packages (2.9.0)\n",
            "Requirement already satisfied: click>=7.0 in /usr/local/lib/python3.10/dist-packages (from ray) (8.1.7)\n",
            "Requirement already satisfied: filelock in /usr/local/lib/python3.10/dist-packages (from ray) (3.13.1)\n",
            "Requirement already satisfied: jsonschema in /usr/local/lib/python3.10/dist-packages (from ray) (4.19.2)\n",
            "Requirement already satisfied: msgpack<2.0.0,>=1.0.0 in /usr/local/lib/python3.10/dist-packages (from ray) (1.0.7)\n",
            "Requirement already satisfied: packaging in /usr/local/lib/python3.10/dist-packages (from ray) (23.2)\n",
            "Requirement already satisfied: protobuf!=3.19.5,>=3.15.3 in /usr/local/lib/python3.10/dist-packages (from ray) (3.20.3)\n",
            "Requirement already satisfied: pyyaml in /usr/local/lib/python3.10/dist-packages (from ray) (6.0.1)\n",
            "Requirement already satisfied: aiosignal in /usr/local/lib/python3.10/dist-packages (from ray) (1.3.1)\n",
            "Requirement already satisfied: frozenlist in /usr/local/lib/python3.10/dist-packages (from ray) (1.4.1)\n",
            "Requirement already satisfied: requests in /usr/local/lib/python3.10/dist-packages (from ray) (2.31.0)\n",
            "Requirement already satisfied: attrs>=22.2.0 in /usr/local/lib/python3.10/dist-packages (from jsonschema->ray) (23.2.0)\n",
            "Requirement already satisfied: jsonschema-specifications>=2023.03.6 in /usr/local/lib/python3.10/dist-packages (from jsonschema->ray) (2023.12.1)\n",
            "Requirement already satisfied: referencing>=0.28.4 in /usr/local/lib/python3.10/dist-packages (from jsonschema->ray) (0.32.1)\n",
            "Requirement already satisfied: rpds-py>=0.7.1 in /usr/local/lib/python3.10/dist-packages (from jsonschema->ray) (0.16.2)\n",
            "\u001b[31mERROR: Operation cancelled by user\u001b[0m\u001b[31m\n",
            "\u001b[0mTraceback (most recent call last):\n",
            "  File \"/usr/local/lib/python3.10/dist-packages/pip/_internal/cli/base_command.py\", line 169, in exc_logging_wrapper\n",
            "    status = run_func(*args)\n",
            "  File \"/usr/local/lib/python3.10/dist-packages/pip/_internal/cli/req_command.py\", line 242, in wrapper\n",
            "    return func(self, options, args)\n",
            "  File \"/usr/local/lib/python3.10/dist-packages/pip/_internal/commands/install.py\", line 377, in run\n",
            "    requirement_set = resolver.resolve(\n",
            "  File \"/usr/local/lib/python3.10/dist-packages/pip/_internal/resolution/resolvelib/resolver.py\", line 92, in resolve\n",
            "    result = self._result = resolver.resolve(\n",
            "  File \"/usr/local/lib/python3.10/dist-packages/pip/_vendor/resolvelib/resolvers.py\", line 546, in resolve\n",
            "    state = resolution.resolve(requirements, max_rounds=max_rounds)\n",
            "  File \"/usr/local/lib/python3.10/dist-packages/pip/_vendor/resolvelib/resolvers.py\", line 443, in resolve\n",
            "    newly_unsatisfied_names = {\n",
            "  File \"/usr/local/lib/python3.10/dist-packages/pip/_vendor/resolvelib/resolvers.py\", line 447, in <setcomp>\n",
            "    and not self._is_current_pin_satisfying(key, criterion)\n",
            "  File \"/usr/local/lib/python3.10/dist-packages/pip/_vendor/resolvelib/resolvers.py\", line 222, in _is_current_pin_satisfying\n",
            "    return all(\n",
            "  File \"/usr/local/lib/python3.10/dist-packages/pip/_vendor/resolvelib/resolvers.py\", line 223, in <genexpr>\n",
            "    self._p.is_satisfied_by(requirement=r, candidate=current_pin)\n",
            "  File \"/usr/local/lib/python3.10/dist-packages/pip/_internal/resolution/resolvelib/provider.py\", line 240, in is_satisfied_by\n",
            "    return requirement.is_satisfied_by(candidate)\n",
            "  File \"/usr/local/lib/python3.10/dist-packages/pip/_internal/resolution/resolvelib/requirements.py\", line 92, in is_satisfied_by\n",
            "    return spec.contains(candidate.version, prereleases=True)\n",
            "  File \"/usr/local/lib/python3.10/dist-packages/pip/_internal/resolution/resolvelib/candidates.py\", line 379, in version\n",
            "    return self.dist.version\n",
            "  File \"/usr/local/lib/python3.10/dist-packages/pip/_internal/metadata/pkg_resources.py\", line 168, in version\n",
            "    return parse_version(self._dist.version)\n",
            "  File \"/usr/local/lib/python3.10/dist-packages/pip/_vendor/packaging/version.py\", line 49, in parse\n",
            "    return Version(version)\n",
            "  File \"/usr/local/lib/python3.10/dist-packages/pip/_vendor/packaging/version.py\", line 281, in __init__\n",
            "    self._key = _cmpkey(\n",
            "  File \"/usr/local/lib/python3.10/dist-packages/pip/_vendor/packaging/version.py\", line 459, in _cmpkey\n",
            "    reversed(list(itertools.dropwhile(lambda x: x == 0, reversed(release))))\n",
            "KeyboardInterrupt\n",
            "\n",
            "During handling of the above exception, another exception occurred:\n",
            "\n",
            "Traceback (most recent call last):\n",
            "  File \"/usr/local/bin/pip3\", line 8, in <module>\n",
            "    sys.exit(main())\n",
            "  File \"/usr/local/lib/python3.10/dist-packages/pip/_internal/cli/main.py\", line 79, in main\n",
            "    return command.main(cmd_args)\n",
            "  File \"/usr/local/lib/python3.10/dist-packages/pip/_internal/cli/base_command.py\", line 101, in main\n",
            "    return self._main(args)\n",
            "  File \"/usr/local/lib/python3.10/dist-packages/pip/_internal/cli/base_command.py\", line 223, in _main\n",
            "    return run(options, args)\n",
            "  File \"/usr/local/lib/python3.10/dist-packages/pip/_internal/cli/base_command.py\", line 207, in exc_logging_wrapper\n",
            "    logger.debug(\"Exception information:\", exc_info=True)\n",
            "  File \"/usr/lib/python3.10/logging/__init__.py\", line 1465, in debug\n",
            "    self._log(DEBUG, msg, args, **kwargs)\n",
            "  File \"/usr/lib/python3.10/logging/__init__.py\", line 1624, in _log\n",
            "    self.handle(record)\n",
            "  File \"/usr/lib/python3.10/logging/__init__.py\", line 1634, in handle\n",
            "    self.callHandlers(record)\n",
            "  File \"/usr/lib/python3.10/logging/__init__.py\", line 1696, in callHandlers\n",
            "    hdlr.handle(record)\n",
            "  File \"/usr/lib/python3.10/logging/__init__.py\", line 968, in handle\n",
            "    self.emit(record)\n",
            "  File \"/usr/lib/python3.10/logging/handlers.py\", line 75, in emit\n",
            "    logging.FileHandler.emit(self, record)\n",
            "  File \"/usr/lib/python3.10/logging/__init__.py\", line 1218, in emit\n",
            "    StreamHandler.emit(self, record)\n",
            "  File \"/usr/lib/python3.10/logging/__init__.py\", line 1100, in emit\n",
            "    msg = self.format(record)\n",
            "  File \"/usr/lib/python3.10/logging/__init__.py\", line 943, in format\n",
            "    return fmt.format(record)\n",
            "  File \"/usr/local/lib/python3.10/dist-packages/pip/_internal/utils/logging.py\", line 112, in format\n",
            "    formatted = super().format(record)\n",
            "  File \"/usr/lib/python3.10/logging/__init__.py\", line 686, in format\n",
            "    record.exc_text = self.formatException(record.exc_info)\n",
            "  File \"/usr/lib/python3.10/logging/__init__.py\", line 636, in formatException\n",
            "    traceback.print_exception(ei[0], ei[1], tb, None, sio)\n",
            "  File \"/usr/lib/python3.10/traceback.py\", line 119, in print_exception\n",
            "    te = TracebackException(type(value), value, tb, limit=limit, compact=True)\n",
            "  File \"/usr/lib/python3.10/traceback.py\", line 502, in __init__\n",
            "    self.stack = StackSummary.extract(\n",
            "  File \"/usr/lib/python3.10/traceback.py\", line 383, in extract\n",
            "    f.line\n",
            "  File \"/usr/lib/python3.10/traceback.py\", line 306, in line\n",
            "    self._line = linecache.getline(self.filename, self.lineno)\n",
            "  File \"/usr/lib/python3.10/linecache.py\", line 30, in getline\n",
            "    lines = getlines(filename, module_globals)\n",
            "  File \"/usr/lib/python3.10/linecache.py\", line 46, in getlines\n",
            "    return updatecache(filename, module_globals)\n",
            "  File \"/usr/lib/python3.10/linecache.py\", line 136, in updatecache\n",
            "    with tokenize.open(fullname) as fp:\n",
            "  File \"/usr/lib/python3.10/tokenize.py\", line 396, in open\n",
            "    encoding, lines = detect_encoding(buffer.readline)\n",
            "  File \"/usr/lib/python3.10/tokenize.py\", line 365, in detect_encoding\n",
            "    first = read_or_stop()\n",
            "  File \"/usr/lib/python3.10/tokenize.py\", line 323, in read_or_stop\n",
            "    return readline()\n",
            "KeyboardInterrupt\n",
            "^C\n",
            "Requirement already satisfied: modin[ray] in /usr/local/lib/python3.10/dist-packages (0.26.0)\n",
            "Requirement already satisfied: pandas<2.2,>=2.1 in /usr/local/lib/python3.10/dist-packages (from modin[ray]) (2.1.4)\n",
            "Requirement already satisfied: packaging>=21.0 in /usr/local/lib/python3.10/dist-packages (from modin[ray]) (23.2)\n",
            "Requirement already satisfied: numpy>=1.22.4 in /usr/local/lib/python3.10/dist-packages (from modin[ray]) (1.23.5)\n",
            "Requirement already satisfied: fsspec>=2022.05.0 in /usr/local/lib/python3.10/dist-packages (from modin[ray]) (2023.6.0)\n",
            "Requirement already satisfied: psutil>=5.8.0 in /usr/local/lib/python3.10/dist-packages (from modin[ray]) (5.9.5)\n",
            "Requirement already satisfied: ray[default]!=2.5.0,>=1.13.0 in /usr/local/lib/python3.10/dist-packages (from modin[ray]) (2.9.0)\n",
            "Requirement already satisfied: pyarrow>=7.0.0 in /usr/local/lib/python3.10/dist-packages (from modin[ray]) (10.0.1)\n",
            "Requirement already satisfied: pydantic<2 in /usr/local/lib/python3.10/dist-packages (from modin[ray]) (1.10.13)\n",
            "Requirement already satisfied: python-dateutil>=2.8.2 in /usr/local/lib/python3.10/dist-packages (from pandas<2.2,>=2.1->modin[ray]) (2.8.2)\n",
            "Requirement already satisfied: pytz>=2020.1 in /usr/local/lib/python3.10/dist-packages (from pandas<2.2,>=2.1->modin[ray]) (2023.3.post1)\n",
            "Requirement already satisfied: tzdata>=2022.1 in /usr/local/lib/python3.10/dist-packages (from pandas<2.2,>=2.1->modin[ray]) (2023.4)\n",
            "Requirement already satisfied: typing-extensions>=4.2.0 in /usr/local/lib/python3.10/dist-packages (from pydantic<2->modin[ray]) (4.5.0)\n",
            "Requirement already satisfied: click>=7.0 in /usr/local/lib/python3.10/dist-packages (from ray[default]!=2.5.0,>=1.13.0->modin[ray]) (8.1.7)\n",
            "Requirement already satisfied: filelock in /usr/local/lib/python3.10/dist-packages (from ray[default]!=2.5.0,>=1.13.0->modin[ray]) (3.13.1)\n",
            "Requirement already satisfied: jsonschema in /usr/local/lib/python3.10/dist-packages (from ray[default]!=2.5.0,>=1.13.0->modin[ray]) (4.19.2)\n",
            "Requirement already satisfied: msgpack<2.0.0,>=1.0.0 in /usr/local/lib/python3.10/dist-packages (from ray[default]!=2.5.0,>=1.13.0->modin[ray]) (1.0.7)\n",
            "Requirement already satisfied: protobuf!=3.19.5,>=3.15.3 in /usr/local/lib/python3.10/dist-packages (from ray[default]!=2.5.0,>=1.13.0->modin[ray]) (3.20.3)\n",
            "Requirement already satisfied: pyyaml in /usr/local/lib/python3.10/dist-packages (from ray[default]!=2.5.0,>=1.13.0->modin[ray]) (6.0.1)\n",
            "Requirement already satisfied: aiosignal in /usr/local/lib/python3.10/dist-packages (from ray[default]!=2.5.0,>=1.13.0->modin[ray]) (1.3.1)\n",
            "Requirement already satisfied: frozenlist in /usr/local/lib/python3.10/dist-packages (from ray[default]!=2.5.0,>=1.13.0->modin[ray]) (1.4.1)\n",
            "Requirement already satisfied: requests in /usr/local/lib/python3.10/dist-packages (from ray[default]!=2.5.0,>=1.13.0->modin[ray]) (2.31.0)\n",
            "Requirement already satisfied: aiohttp>=3.7 in /usr/local/lib/python3.10/dist-packages (from ray[default]!=2.5.0,>=1.13.0->modin[ray]) (3.9.1)\n",
            "Requirement already satisfied: aiohttp-cors in /usr/local/lib/python3.10/dist-packages (from ray[default]!=2.5.0,>=1.13.0->modin[ray]) (0.7.0)\n",
            "Requirement already satisfied: colorful in /usr/local/lib/python3.10/dist-packages (from ray[default]!=2.5.0,>=1.13.0->modin[ray]) (0.5.6)\n",
            "Requirement already satisfied: py-spy>=0.2.0 in /usr/local/lib/python3.10/dist-packages (from ray[default]!=2.5.0,>=1.13.0->modin[ray]) (0.3.14)\n",
            "Requirement already satisfied: gpustat>=1.0.0 in /usr/local/lib/python3.10/dist-packages (from ray[default]!=2.5.0,>=1.13.0->modin[ray]) (1.1.1)\n",
            "Requirement already satisfied: opencensus in /usr/local/lib/python3.10/dist-packages (from ray[default]!=2.5.0,>=1.13.0->modin[ray]) (0.11.4)\n",
            "Requirement already satisfied: prometheus-client>=0.7.1 in /usr/local/lib/python3.10/dist-packages (from ray[default]!=2.5.0,>=1.13.0->modin[ray]) (0.19.0)\n",
            "Requirement already satisfied: smart-open in /usr/local/lib/python3.10/dist-packages (from ray[default]!=2.5.0,>=1.13.0->modin[ray]) (6.4.0)\n",
            "Requirement already satisfied: virtualenv<20.21.1,>=20.0.24 in /usr/local/lib/python3.10/dist-packages (from ray[default]!=2.5.0,>=1.13.0->modin[ray]) (20.21.0)\n",
            "Requirement already satisfied: grpcio>=1.42.0 in /usr/local/lib/python3.10/dist-packages (from ray[default]!=2.5.0,>=1.13.0->modin[ray]) (1.60.0)\n",
            "Requirement already satisfied: attrs>=17.3.0 in /usr/local/lib/python3.10/dist-packages (from aiohttp>=3.7->ray[default]!=2.5.0,>=1.13.0->modin[ray]) (23.2.0)\n",
            "Requirement already satisfied: multidict<7.0,>=4.5 in /usr/local/lib/python3.10/dist-packages (from aiohttp>=3.7->ray[default]!=2.5.0,>=1.13.0->modin[ray]) (6.0.4)\n",
            "Requirement already satisfied: yarl<2.0,>=1.0 in /usr/local/lib/python3.10/dist-packages (from aiohttp>=3.7->ray[default]!=2.5.0,>=1.13.0->modin[ray]) (1.9.4)\n",
            "Requirement already satisfied: async-timeout<5.0,>=4.0 in /usr/local/lib/python3.10/dist-packages (from aiohttp>=3.7->ray[default]!=2.5.0,>=1.13.0->modin[ray]) (4.0.3)\n",
            "Requirement already satisfied: nvidia-ml-py>=11.450.129 in /usr/local/lib/python3.10/dist-packages (from gpustat>=1.0.0->ray[default]!=2.5.0,>=1.13.0->modin[ray]) (12.535.133)\n",
            "Requirement already satisfied: blessed>=1.17.1 in /usr/local/lib/python3.10/dist-packages (from gpustat>=1.0.0->ray[default]!=2.5.0,>=1.13.0->modin[ray]) (1.20.0)\n",
            "Requirement already satisfied: six>=1.5 in /usr/local/lib/python3.10/dist-packages (from python-dateutil>=2.8.2->pandas<2.2,>=2.1->modin[ray]) (1.16.0)\n",
            "Requirement already satisfied: distlib<1,>=0.3.6 in /usr/local/lib/python3.10/dist-packages (from virtualenv<20.21.1,>=20.0.24->ray[default]!=2.5.0,>=1.13.0->modin[ray]) (0.3.8)\n",
            "Requirement already satisfied: platformdirs<4,>=2.4 in /usr/local/lib/python3.10/dist-packages (from virtualenv<20.21.1,>=20.0.24->ray[default]!=2.5.0,>=1.13.0->modin[ray]) (3.11.0)\n",
            "Requirement already satisfied: jsonschema-specifications>=2023.03.6 in /usr/local/lib/python3.10/dist-packages (from jsonschema->ray[default]!=2.5.0,>=1.13.0->modin[ray]) (2023.12.1)\n",
            "Requirement already satisfied: referencing>=0.28.4 in /usr/local/lib/python3.10/dist-packages (from jsonschema->ray[default]!=2.5.0,>=1.13.0->modin[ray]) (0.32.1)\n",
            "Requirement already satisfied: rpds-py>=0.7.1 in /usr/local/lib/python3.10/dist-packages (from jsonschema->ray[default]!=2.5.0,>=1.13.0->modin[ray]) (0.16.2)\n",
            "Requirement already satisfied: opencensus-context>=0.1.3 in /usr/local/lib/python3.10/dist-packages (from opencensus->ray[default]!=2.5.0,>=1.13.0->modin[ray]) (0.1.3)\n",
            "Requirement already satisfied: google-api-core<3.0.0,>=1.0.0 in /usr/local/lib/python3.10/dist-packages (from opencensus->ray[default]!=2.5.0,>=1.13.0->modin[ray]) (2.11.1)\n",
            "Requirement already satisfied: charset-normalizer<4,>=2 in /usr/local/lib/python3.10/dist-packages (from requests->ray[default]!=2.5.0,>=1.13.0->modin[ray]) (3.3.2)\n",
            "Requirement already satisfied: idna<4,>=2.5 in /usr/local/lib/python3.10/dist-packages (from requests->ray[default]!=2.5.0,>=1.13.0->modin[ray]) (3.6)\n",
            "Requirement already satisfied: urllib3<3,>=1.21.1 in /usr/local/lib/python3.10/dist-packages (from requests->ray[default]!=2.5.0,>=1.13.0->modin[ray]) (2.0.7)\n",
            "Requirement already satisfied: certifi>=2017.4.17 in /usr/local/lib/python3.10/dist-packages (from requests->ray[default]!=2.5.0,>=1.13.0->modin[ray]) (2023.11.17)\n",
            "Requirement already satisfied: wcwidth>=0.1.4 in /usr/local/lib/python3.10/dist-packages (from blessed>=1.17.1->gpustat>=1.0.0->ray[default]!=2.5.0,>=1.13.0->modin[ray]) (0.2.12)\n",
            "Requirement already satisfied: googleapis-common-protos<2.0.dev0,>=1.56.2 in /usr/local/lib/python3.10/dist-packages (from google-api-core<3.0.0,>=1.0.0->opencensus->ray[default]!=2.5.0,>=1.13.0->modin[ray]) (1.62.0)\n",
            "Requirement already satisfied: google-auth<3.0.dev0,>=2.14.1 in /usr/local/lib/python3.10/dist-packages (from google-api-core<3.0.0,>=1.0.0->opencensus->ray[default]!=2.5.0,>=1.13.0->modin[ray]) (2.17.3)\n",
            "Requirement already satisfied: cachetools<6.0,>=2.0.0 in /usr/local/lib/python3.10/dist-packages (from google-auth<3.0.dev0,>=2.14.1->google-api-core<3.0.0,>=1.0.0->opencensus->ray[default]!=2.5.0,>=1.13.0->modin[ray]) (5.3.2)\n",
            "Requirement already satisfied: pyasn1-modules>=0.2.1 in /usr/local/lib/python3.10/dist-packages (from google-auth<3.0.dev0,>=2.14.1->google-api-core<3.0.0,>=1.0.0->opencensus->ray[default]!=2.5.0,>=1.13.0->modin[ray]) (0.3.0)\n",
            "Requirement already satisfied: rsa<5,>=3.1.4 in /usr/local/lib/python3.10/dist-packages (from google-auth<3.0.dev0,>=2.14.1->google-api-core<3.0.0,>=1.0.0->opencensus->ray[default]!=2.5.0,>=1.13.0->modin[ray]) (4.9)\n",
            "Requirement already satisfied: pyasn1<0.6.0,>=0.4.6 in /usr/local/lib/python3.10/dist-packages (from pyasn1-modules>=0.2.1->google-auth<3.0.dev0,>=2.14.1->google-api-core<3.0.0,>=1.0.0->opencensus->ray[default]!=2.5.0,>=1.13.0->modin[ray]) (0.5.1)\n",
            "\u001b[31mERROR: Operation cancelled by user\u001b[0m\u001b[31m\n",
            "\u001b[0mRequirement already satisfied: pandas in /usr/local/lib/python3.10/dist-packages (2.1.4)\n",
            "Requirement already satisfied: numpy<2,>=1.22.4 in /usr/local/lib/python3.10/dist-packages (from pandas) (1.23.5)\n",
            "Requirement already satisfied: python-dateutil>=2.8.2 in /usr/local/lib/python3.10/dist-packages (from pandas) (2.8.2)\n",
            "Requirement already satisfied: pytz>=2020.1 in /usr/local/lib/python3.10/dist-packages (from pandas) (2023.3.post1)\n",
            "Requirement already satisfied: tzdata>=2022.1 in /usr/local/lib/python3.10/dist-packages (from pandas) (2023.4)\n",
            "Requirement already satisfied: six>=1.5 in /usr/local/lib/python3.10/dist-packages (from python-dateutil>=2.8.2->pandas) (1.16.0)\n"
          ]
        }
      ],
      "source": [
        "!pip install ray\n",
        "!pip install modin[ray]\n",
        "!pip install pandas\n",
        "!pip install dask\n",
        "!pip install pyyaml\n",
        "\n",
        "import pandas as pd\n",
        "import dask.dataframe as dd\n",
        "import modin.pandas as mp\n",
        "import ray\n",
        "import yaml\n",
        "import os\n",
        "import time\n",
        "import gzip\n",
        "from google.colab import drive\n",
        "\n",
        "drive.mount('/content/drive')\n",
        "\n",
        "file_path = '/content/drive/My Drive/unbalaced_20_80_dataset.csv'\n",
        "\n",
        "def read_with_pandas(file_path):\n",
        "    start_time = time.time()\n",
        "    df_pandas = pd.read_csv(file_path)\n",
        "    elapsed_time = time.time() - start_time\n",
        "    print(\"Pandas Time:\", elapsed_time)\n",
        "    return df_pandas\n",
        "\n",
        "def read_with_dask(file_path):\n",
        "    start_time = time.time()\n",
        "    df_dask = dd.read_csv(file_path)\n",
        "    elapsed_time = time.time() - start_time\n",
        "    print(\"Dask Time:\", elapsed_time)\n",
        "    return df_dask\n",
        "\n",
        "ray.shutdown()\n",
        "ray.init(ignore_reinit_error=True)\n",
        "\n",
        "def read_with_modin(file_path):\n",
        "    start_time = time.time()\n",
        "    df_modin = mp.read_csv(file_path)\n",
        "    elapsed_time = time.time() - start_time\n",
        "    print(\"Modin Time:\", elapsed_time)\n",
        "    return df_modin\n",
        "\n",
        "def validate_columns(df):\n",
        "    df.columns = df.columns.str.replace(' ', '_').str.replace('[^\\\\w\\\\s]', '')\n",
        "    return df\n",
        "\n",
        "def create_yaml(df, yaml_path):\n",
        "    schema = {'columns': df.columns.tolist()}\n",
        "    with open(yaml_path, 'w') as file:\n",
        "        yaml.dump(schema, file, default_flow_style=False)\n",
        "\n",
        "def validate_with_yaml(df, yaml_path):\n",
        "    with open(yaml_path, 'r') as file:\n",
        "        schema = yaml.safe_load(file)\n",
        "    assert schema['columns'] == df.columns.tolist(), \"Columns do not match with YAML file.\"\n",
        "\n",
        "def write_and_summarize(df, output_path):\n",
        "    df.to_csv(output_path, sep='|', index=False, compression='gzip')\n",
        "    summary = {\n",
        "        'rows': len(df),\n",
        "        'columns': len(df.columns),\n",
        "        'size': os.path.getsize(output_path)\n",
        "    }\n",
        "    return summary\n",
        "\n",
        "yaml_path = '/content/schema.yaml'\n",
        "output_path = '/content/output_file.gz'\n",
        "\n",
        "df = read_with_pandas(file_path)\n",
        "df = validate_columns(df)\n",
        "\n",
        "create_yaml(df, yaml_path)\n",
        "validate_with_yaml(df, yaml_path)\n",
        "\n",
        "summary = write_and_summarize(df, output_path)\n",
        "\n",
        "print(summary)\n"
      ]
    }
  ]
}